[2023-06-02T08:54:47.568+0300] {taskinstance.py:1103} INFO - Dependencies all met for dep_context=non-requeueable deps ti=<TaskInstance: space_missions.get_images scheduled__2023-05-29T00:00:00+00:00 [queued]>
[2023-06-02T08:54:47.579+0300] {taskinstance.py:1103} INFO - Dependencies all met for dep_context=requeueable deps ti=<TaskInstance: space_missions.get_images scheduled__2023-05-29T00:00:00+00:00 [queued]>
[2023-06-02T08:54:47.580+0300] {taskinstance.py:1308} INFO - Starting attempt 5 of 6
[2023-06-02T08:54:47.615+0300] {taskinstance.py:1327} INFO - Executing <Task(PythonOperator): get_images> on 2023-05-29 00:00:00+00:00
[2023-06-02T08:54:47.621+0300] {standard_task_runner.py:57} INFO - Started process 20446 to run task
[2023-06-02T08:54:47.627+0300] {standard_task_runner.py:84} INFO - Running: ['***', 'tasks', 'run', 'space_missions', 'get_images', 'scheduled__2023-05-29T00:00:00+00:00', '--job-id', '31', '--raw', '--subdir', 'DAGS_FOLDER/space_missions.py', '--cfg-path', '/tmp/tmp734t2m47']
[2023-06-02T08:54:47.630+0300] {standard_task_runner.py:85} INFO - Job 31: Subtask get_images
[2023-06-02T08:54:47.727+0300] {task_command.py:410} INFO - Running <TaskInstance: space_missions.get_images scheduled__2023-05-29T00:00:00+00:00 [running]> on host mutwiri
[2023-06-02T08:54:48.043+0300] {taskinstance.py:1545} INFO - Exporting env vars: AIRFLOW_CTX_DAG_EMAIL='franklinmutwiri41@gmail.com' AIRFLOW_CTX_DAG_OWNER='***' AIRFLOW_CTX_DAG_ID='space_missions' AIRFLOW_CTX_TASK_ID='get_images' AIRFLOW_CTX_EXECUTION_DATE='2023-05-29T00:00:00+00:00' AIRFLOW_CTX_TRY_NUMBER='5' AIRFLOW_CTX_DAG_RUN_ID='scheduled__2023-05-29T00:00:00+00:00'
[2023-06-02T08:54:48.044+0300] {taskinstance.py:1824} ERROR - Task failed with exception
Traceback (most recent call last):
  File "/usr/lib/python3.10/pathlib.py", line 1175, in mkdir
    self._accessor.mkdir(self, mode)
FileNotFoundError: [Errno 2] No such file or directory: '/airflow/images'

During handling of the above exception, another exception occurred:

Traceback (most recent call last):
  File "/home/mutwiri/airflow/airflow_env/lib/python3.10/site-packages/airflow/operators/python.py", line 181, in execute
    return_value = self.execute_callable()
  File "/home/mutwiri/airflow/airflow_env/lib/python3.10/site-packages/airflow/operators/python.py", line 198, in execute_callable
    return self.python_callable(*self.op_args, **self.op_kwargs)
  File "/home/mutwiri/airflow/dags/space_missions.py", line 32, in get_images
    pathlib.Path("/airflow/images").mkdir(parents=True, exist_ok=True)
  File "/usr/lib/python3.10/pathlib.py", line 1179, in mkdir
    self.parent.mkdir(parents=True, exist_ok=True)
  File "/usr/lib/python3.10/pathlib.py", line 1175, in mkdir
    self._accessor.mkdir(self, mode)
PermissionError: [Errno 13] Permission denied: '/airflow'
[2023-06-02T08:54:48.065+0300] {taskinstance.py:1345} INFO - Marking task as UP_FOR_RETRY. dag_id=space_missions, task_id=get_images, execution_date=20230529T000000, start_date=20230602T055447, end_date=20230602T055448
[2023-06-02T08:54:48.092+0300] {standard_task_runner.py:104} ERROR - Failed to execute job 31 for task get_images ([Errno 13] Permission denied: '/airflow'; 20446)
[2023-06-02T08:54:48.119+0300] {local_task_job_runner.py:225} INFO - Task exited with return code 1
[2023-06-02T08:54:48.173+0300] {taskinstance.py:2651} INFO - 0 downstream tasks scheduled from follow-on schedule check
