[2023-06-02T08:48:41.619+0300] {taskinstance.py:1103} INFO - Dependencies all met for dep_context=non-requeueable deps ti=<TaskInstance: space_missions.get_images scheduled__2023-05-29T00:00:00+00:00 [queued]>
[2023-06-02T08:48:41.635+0300] {taskinstance.py:1103} INFO - Dependencies all met for dep_context=requeueable deps ti=<TaskInstance: space_missions.get_images scheduled__2023-05-29T00:00:00+00:00 [queued]>
[2023-06-02T08:48:41.636+0300] {taskinstance.py:1308} INFO - Starting attempt 3 of 6
[2023-06-02T08:48:41.683+0300] {taskinstance.py:1327} INFO - Executing <Task(PythonOperator): get_images> on 2023-05-29 00:00:00+00:00
[2023-06-02T08:48:41.689+0300] {standard_task_runner.py:57} INFO - Started process 18294 to run task
[2023-06-02T08:48:41.705+0300] {standard_task_runner.py:84} INFO - Running: ['***', 'tasks', 'run', 'space_missions', 'get_images', 'scheduled__2023-05-29T00:00:00+00:00', '--job-id', '29', '--raw', '--subdir', 'DAGS_FOLDER/space_missions.py', '--cfg-path', '/tmp/tmpnfwqonud']
[2023-06-02T08:48:41.725+0300] {standard_task_runner.py:85} INFO - Job 29: Subtask get_images
[2023-06-02T08:48:41.879+0300] {task_command.py:410} INFO - Running <TaskInstance: space_missions.get_images scheduled__2023-05-29T00:00:00+00:00 [running]> on host mutwiri
[2023-06-02T08:48:42.211+0300] {taskinstance.py:1545} INFO - Exporting env vars: AIRFLOW_CTX_DAG_EMAIL='franklinmutwiri41@gmail.com' AIRFLOW_CTX_DAG_OWNER='***' AIRFLOW_CTX_DAG_ID='space_missions' AIRFLOW_CTX_TASK_ID='get_images' AIRFLOW_CTX_EXECUTION_DATE='2023-05-29T00:00:00+00:00' AIRFLOW_CTX_TRY_NUMBER='3' AIRFLOW_CTX_DAG_RUN_ID='scheduled__2023-05-29T00:00:00+00:00'
[2023-06-02T08:48:44.142+0300] {taskinstance.py:1824} ERROR - Task failed with exception
Traceback (most recent call last):
  File "/home/mutwiri/airflow/airflow_env/lib/python3.10/site-packages/airflow/operators/python.py", line 181, in execute
    return_value = self.execute_callable()
  File "/home/mutwiri/airflow/airflow_env/lib/python3.10/site-packages/airflow/operators/python.py", line 198, in execute_callable
    return self.python_callable(*self.op_args, **self.op_kwargs)
  File "/home/mutwiri/airflow/dags/space_missions.py", line 41, in get_images
    with open (target_file, "wb" ) as target:
FileNotFoundError: [Errno 2] No such file or directory: '../images/falcon2520925_image_20210922155355.jpeg'
[2023-06-02T08:48:44.184+0300] {taskinstance.py:1345} INFO - Marking task as UP_FOR_RETRY. dag_id=space_missions, task_id=get_images, execution_date=20230529T000000, start_date=20230602T054841, end_date=20230602T054844
[2023-06-02T08:48:44.218+0300] {standard_task_runner.py:104} ERROR - Failed to execute job 29 for task get_images ([Errno 2] No such file or directory: '../images/falcon2520925_image_20210922155355.jpeg'; 18294)
[2023-06-02T08:48:44.245+0300] {local_task_job_runner.py:225} INFO - Task exited with return code 1
[2023-06-02T08:48:44.285+0300] {taskinstance.py:2651} INFO - 0 downstream tasks scheduled from follow-on schedule check
